C++ 异常的向上传播（Exception Propagation）是指异常在函数调用栈中从深层函数向顶层函数传递的过程。这是 C++ 异常处理机制的核心特性之一。

## 异常传播的基本机制

### 1. 自动栈展开（Stack Unwinding）

当异常被抛出时，C++ 运行时系统会沿着调用栈向上查找匹配的 `catch` 块，这个过程称为栈展开：

```cpp
#include <iostream>
#include <stdexcept>

void functionC() {
    std::cout << "Entering functionC" << std::endl;
    throw std::runtime_error("Error in functionC");
    std::cout << "This line won't execute" << std::endl; // 不会执行
}

void functionB() {
    std::cout << "Entering functionB" << std::endl;
    functionC();
    std::cout << "Leaving functionB" << std::endl; // 不会执行
}

void functionA() {
    std::cout << "Entering functionA" << std::endl;
    functionB();
    std::cout << "Leaving functionA" << std::endl; // 不会执行
}

int main() {
    try {
        functionA();
    }
    catch (const std::runtime_error& e) {
        std::cout << "Caught exception: " << e.what() << std::endl;
    }
    return 0;
}
```

**输出：**
```
Entering functionA
Entering functionB
Entering functionC
Caught exception: Error in functionC
```

## 异常传播中的资源管理

### 2. RAII 与栈展开

在栈展开过程中，局部对象的析构函数会被自动调用，这是 RAII 模式的关键：

```cpp
#include <iostream>
#include <memory>

class Resource {
private:
    std::string name;
public:
    Resource(const std::string& n) : name(n) {
        std::cout << "Resource " << name << " acquired" << std::endl;
    }
    
    ~Resource() {
        std::cout << "Resource " << name << " released" << std::endl;
    }
};

void riskyOperation() {
    Resource res1("A");
    Resource res2("B");
    
    throw std::runtime_error("Something went wrong!");
    
    // 以下代码不会执行
    Resource res3("C");
}

int main() {
    try {
        riskyOperation();
    }
    catch (const std::exception& e) {
        std::cout << "Exception: " << e.what() << std::endl;
    }
    return 0;
}
```

**输出：**
```
Resource A acquired
Resource B acquired
Resource B released
Resource A released
Exception: Something went wrong
```

## 异常传播的控制

### 3. 重新抛出异常（Rethrowing）

可以在 `catch` 块中重新抛出当前异常，让上层调用者继续处理：

```cpp
#include <iostream>

void logAndRethrow() {
    try {
        // 可能抛出异常的代码
        throw std::runtime_error("Original error");
    }
    catch (const std::exception& e) {
        std::cout << "Logging error: " << e.what() << std::endl;
        // 重新抛出异常
        throw; // 注意：没有指定异常对象
    }
}

void logAndThrowNew() {
    try {
        throw std::runtime_error("Original error");
    }
    catch (const std::exception& e) {
        std::cout << "Logging: " << e.what() << std::endl;
        // 抛出新的异常
        throw std::logic_error("New error based on original");
    }
}

int main() {
    try {
        logAndRethrow();
    }
    catch (const std::runtime_error& e) {
        std::cout << "Caught runtime_error: " << e.what() << std::endl;
    }
    
    try {
        logAndThrowNew();
    }
    catch (const std::logic_error& e) {
        std::cout << "Caught logic_error: " << e.what() << std::endl;
    }
    return 0;
}
```

## 异常传播的嵌套处理

### 4. 多层异常处理

异常可以在多个层级被部分处理并继续传播：

```cpp
#include <iostream>

void level3() {
    throw std::runtime_error("Error from deepest level");
}

void level2() {
    try {
        level3();
    }
    catch (const std::runtime_error& e) {
        std::cout << "Level2: Adding context to: " << e.what() << std::endl;
        // 包装原始异常
        throw std::runtime_error(std::string("Wrapped: ") + e.what());
    }
}

void level1() {
    try {
        level2();
    }
    catch (const std::runtime_error& e) {
        std::cout << "Level1: Final handling of: " << e.what() << std::endl;
    }
}

int main() {
    level1();
    return 0;
}
```

## 异常传播的特殊情况

### 5. 构造函数中的异常

如果构造函数中抛出异常，对象构造被视为失败，析构函数不会被调用：

```cpp
#include <iostream>

class Test {
private:
    int* data;
public:
    Test() {
        std::cout << "Constructor called" << std::endl;
        data = new int[100];  // 分配资源
        
        // 模拟构造函数失败
        throw std::runtime_error("Construction failed");
        
        // 如果上面抛出异常，这里不会执行
    }
    
    ~Test() {
        std::cout << "Destructor called" << std::endl;
        delete[] data;  // 这里不会被执行！
    }
};

int main() {
    try {
        Test obj;  // 构造函数抛出异常
    }
    catch (const std::exception& e) {
        std::cout << "Caught: " << e.what() << std::endl;
        // obj 的析构函数不会被调用！
    }
    return 0;
}
```

**解决方案：使用智能指针或更谨慎的资源管理：**

```cpp
class SafeTest {
private:
    std::unique_ptr<int[]> data;  // 使用智能指针
public:
    SafeTest() {
        std::cout << "SafeTest constructor called" << std::endl;
        data = std::make_unique<int[]>(100);
        
        throw std::runtime_error("Construction failed but resources are safe");
        
        // 即使抛出异常，data 也会被正确释放
    }
    
    ~Test() {
        std::cout << "SafeTest destructor called" << std::endl;
        // 不需要手动释放 data
    }
};
```

### 6. 析构函数中的异常

析构函数中抛出异常是危险的，可能导致程序终止：

```cpp
class Dangerous {
public:
    ~Dangerous() noexcept(false) {
        // 强烈不建议在析构函数中抛出异常！
        throw std::runtime_error("Exception in destructor");
    }
};

int main() {
    try {
        Dangerous d;
    }  // d 离开作用域，析构函数被调用
    catch (...) {
        std::cout << "This might not be reached!" << std::endl;
    }
    return 0;
}
```

## 异常传播的最佳实践

### 7. 异常安全保证

```cpp
#include <vector>
#include <memory>

class ExceptionSafe {
private:
    std::vector<std::unique_ptr<int>> data;
    
public:
    // 强异常安全保证：要么成功，要么保持原状
    void addItem(int value) {
        auto newItem = std::make_unique<int>(value);  // 1. 先创建新资源
        data.push_back(nullptr);                      // 2. 准备位置（可能抛出）
        data.back() = std::move(newItem);             // 3. 安全地设置
    }
    
    // 基本异常安全保证：不泄漏资源，但状态可能改变
    void riskyOperation() {
        auto temp = std::make_unique<int>(42);
        // 一些可能失败的操作
        if (/* 失败条件 */) {
            throw std::runtime_error("Operation failed");
        }
        // 操作成功，提交更改
        data.push_back(std::move(temp));
    }
};
```

### 8. 异常传播策略

```cpp
// 策略1：在底层捕获并处理
void handleAtLowLevel() {
    try {
        // 操作
    }
    catch (const std::exception& e) {
        // 完全处理，不再传播
        std::cout << "Handled: " << e.what() << std::endl;
    }
}

// 策略2：在中间层部分处理并重新抛出
void handleAndRethrow() {
    try {
        // 操作
    }
    catch (const std::exception& e) {
        // 记录日志等部分处理
        std::cout << "Logged: " << e.what() << std::endl;
        throw;  // 继续传播
    }
}

// 策略3：直接传播到顶层
void propagateToTop() {
    // 不捕获，让调用者处理
    // 操作可能抛出异常
}

// 策略4：转换异常类型
void transformException() {
    try {
        // 操作
    }
    catch (const std::runtime_error& e) {
        // 转换为更适合调用者的异常类型
        throw std::logic_error("Transformed: " + std::string(e.what()));
    }
}
```

## 总结

C++ 异常向上传播的关键点：

1. **自动栈展开**：异常沿调用栈向上传播，自动调用局部对象的析构函数
2. **RAII 是关键**：利用析构函数确保资源释放，避免泄漏
3. **重新抛出**：使用 `throw;`（无参数）重新抛出当前异常
4. **构造函数异常**：对象构造失败，析构函数不会被调用
5. **析构函数异常**：极其危险，可能导致程序终止
6. **异常安全**：设计代码时要考虑不同级别的异常安全保证

正确理解和利用异常传播机制，可以写出更健壮、更易维护的 C++ 代码。